<?xml version="1.0" ?>
<robot name="Kauil" xmlns:xacro="http://www.ros.org/wiki/xacro">

<xacro:include filename="$(find Kauil_description)/urdf/materials.xacro" />
<xacro:include filename="$(find Kauil_description)/urdf/Kauil.trans" />
<xacro:include filename="$(find Kauil_description)/urdf/Kauil.gazebo" />

<link name="base_link">
  <inertial>
    <origin xyz="0.0016866872511312947 0.1369871831765067 0.1576312078706392" rpy="0 0 0"/>
    <mass value="92.56633480375484"/>
    <inertia ixx="4.834269" iyy="1.804697" izz="4.708064" ixy="0.021579" iyz="-0.55555" ixz="-0.00717"/>
  </inertial>
  <visual>
    <origin xyz="0 0 0" rpy="0 0 0"/>
    <geometry>
      <mesh filename="package://Kauil_description/meshes/base_link.stl" scale="0.001 0.001 0.001"/>
    </geometry>
    <material name="silver"/>
  </visual>
  <collision>
    <origin xyz="0 0 0" rpy="0 0 0"/>
    <geometry>
      <mesh filename="package://Kauil_description/meshes/base_link.stl" scale="0.001 0.001 0.001"/>
    </geometry>
  </collision>
</link>

<link name="camera_kauil_1">
  <inertial>
    <origin xyz="0.0010451780985420312 -0.007974356683217387 0.03683202882533165" rpy="0 0 0"/>
    <mass value="2.8747629426179175"/>
    <inertia ixx="0.004219" iyy="0.003738" izz="0.00378" ixy="-3.2e-05" iyz="-0.00065" ixz="-9.3e-05"/>
  </inertial>
  <visual>
    <origin xyz="0.00546 -0.37938 -0.23895" rpy="0 0 0"/>
    <geometry>
      <mesh filename="package://Kauil_description/meshes/camera_kauil_1.stl" scale="0.001 0.001 0.001"/>
    </geometry>
    <material name="silver"/>
  </visual>
  <collision>
    <origin xyz="0.00546 -0.37938 -0.23895" rpy="0 0 0"/>
    <geometry>
      <mesh filename="package://Kauil_description/meshes/camera_kauil_1.stl" scale="0.001 0.001 0.001"/>
    </geometry>
  </collision>
</link>

<link name="hokuyo_kauil_1">
  <inertial>
    <origin xyz="-3.662814409416404e-14 -2.1089675922292273e-07 0.041767094902394775" rpy="0 0 0"/>
    <mass value="2.7843842894799833"/>
    <inertia ixx="0.00269" iyy="0.00269" izz="0.00174" ixy="-0.0" iyz="-0.0" ixz="-0.0"/>
  </inertial>
  <visual>
    <origin xyz="-0.000825 -0.351848 -0.35095" rpy="0 0 0"/>
    <geometry>
      <mesh filename="package://Kauil_description/meshes/hokuyo_kauil_1.stl" scale="0.001 0.001 0.001"/>
    </geometry>
    <material name="silver"/>
  </visual>
  <collision>
    <origin xyz="-0.000825 -0.351848 -0.35095" rpy="0 0 0"/>
    <geometry>
      <mesh filename="package://Kauil_description/meshes/hokuyo_kauil_1.stl" scale="0.001 0.001 0.001"/>
    </geometry>
  </collision>
</link>

<link name="r_wheel_1">
  <inertial>
    <origin xyz="0.0054999654570002665 -0.008227290947267998 -0.004494430926877367" rpy="0 0 0"/>
    <mass value="4.059067570781877"/>
    <inertia ixx="0.016884" iyy="0.009874" izz="0.009874" ixy="0.0" iyz="0.0" ixz="-0.0"/>
  </inertial>
  <collision>
    <origin xyz="-0.26 -0.040001 -0.038107" rpy="0 0 0"/>
    <geometry>
      <mesh filename="package://Kauil_description/meshes/r_wheel_1.stl" scale="0.001 0.001 0.001"/>
    </geometry>
  </collision>
</link>

<link name="l_wheel_1">
  <inertial>
    <origin xyz="0.031250024230748685 4.0011892479818734e-08 1.822203452780946e-07" rpy="0 0 0"/>
    <mass value="4.059067721177565"/>
    <inertia ixx="0.016884" iyy="0.009874" izz="0.009874" ixy="0.0" iyz="0.0" ixz="-0.0"/>
  </inertial>
  <collision>
    <origin xyz="0.26 -0.040001 -0.038107" rpy="0 0 0"/>
    <geometry>
      <mesh filename="package://Kauil_description/meshes/l_wheel_1.stl" scale="0.001 0.001 0.001"/>
    </geometry>
  </collision>
</link>

<joint name="camera_joint" type="fixed">
  <origin xyz="-0.00546 0.37938 0.23895" rpy="0 0 0"/>
  <parent link="base_link"/>
  <child link="camera_kauil_1"/>
</joint>

<joint name="hokuyo_joint" type="fixed">
  <origin xyz="0.000825 0.351848 0.35095" rpy="0 0 0"/>
  <parent link="base_link"/>
  <child link="hokuyo_kauil_1"/>
</joint>

<joint name="r_wheel_joint" type="continuous">
  <origin xyz="0.26 0.040001 0.038107" rpy="0 0 0"/>
  <parent link="base_link"/>
  <child link="r_wheel_1"/>
  <axis xyz="-1.0 0.0 0.0"/>
</joint>

<joint name="l_wheel_joint" type="continuous">
  <origin xyz="-0.26 0.040001 0.038107" rpy="0 0 0"/>
  <parent link="base_link"/>
  <child link="l_wheel_1"/>
  <axis xyz="-1.0 0.0 0.0"/>
</joint>

<gazebo>
  <plugin name="differential_drive_controller" filename="libgazebo_ros_diff_drive.so">
    <robotNamespace />
    <alwaysOn>true</alwaysOn>
    <use_sim_time>true</use_sim_time>
    <updateRate>500</updateRate>
    <legacyMode>false</legacyMode>
    <leftJoint>l_wheel_joint</leftJoint>
    <rightJoint>r_wheel_joint</rightJoint>
    <wheelSeparation>0.5380</wheelSeparation>
    <wheelDiameter>0.19</wheelDiameter>
    <torque>500</torque>
    <commandTopic>cmd_vel</commandTopic>
    <odometryTopic>odom</odometryTopic>
    <odometryFrame>odom</odometryFrame>
    <robotBaseFrame>base_link</robotBaseFrame>
    <publishWheelTF>false</publishWheelTF>
    <publishWheelJointState>false</publishWheelJointState>
    <rosDebugLevel>na</rosDebugLevel>
    <wheelAcceleration>0</wheelAcceleration>
    <wheelTorque>500</wheelTorque>
    <odometrySource>world</odometrySource>
    <publishTf>1</publishTf>
    <publishOdomTF>true</publishOdomTF>
  </plugin>
</gazebo>

<!-- hokuyo -->
<gazebo reference="hokuyo_kauil_1">
  <sensor type="gpu_ray" name="head_hokuyo_sensor">
    <pose>0 0 0 0 0 0</pose>
    <visualize>false</visualize>
    <update_rate>40</update_rate>
    <use_sim_time>true</use_sim_time>
    <ray>
      <scan>
        <horizontal>
          <samples>720</samples>
          <resolution>1</resolution>
          <min_angle>-1.570796</min_angle>
          <max_angle>1.570796</max_angle>
        </horizontal>
      </scan>
      <range>
        <min>0.10</min>
        <max>30.0</max>
        <resolution>0.01</resolution>
      </range>
      <noise>
        <type>gaussian</type>
        <!-- Noise parameters based on published spec for Hokuyo laser
              achieving "+-30mm" accuracy at range < 10m.  A mean of 0.0m and
              stddev of 0.01m will put 99.7% of samples within 0.03m of the true
              reading. -->
        <mean>0.0</mean>
        <stddev>0.01</stddev>
      </noise>
    </ray>
    <plugin name="gazebo_ros_head_hokuyo_controller" filename="libgazebo_ros_gpu_laser.so">
      <topicName>/Kauil/laser/scan</topicName>
      <frameName>hokuyo_link</frameName>
    </plugin>
  </sensor>
</gazebo>

<!-- camera -->
<gazebo reference="camera_kauil_1">
  <sensor type="camera" name="camera1">
    <update_rate>30.0</update_rate>
    <use_sim_time>true</use_sim_time>
    <camera name="head">
      <horizontal_fov>1.3962634</horizontal_fov>
      <image>
        <width>800</width>
        <height>800</height>
        <format>R8G8B8</format>
      </image>
      <clip>
        <near>0.02</near>
        <far>300</far>
      </clip>
      <noise>
        <type>gaussian</type>
        <!-- Noise is sampled independently per pixel on each frame.
              That pixel's noise value is added to each of its color
              channels, which at that point lie in the range [0,1]. -->
        <mean>0.0</mean>
        <stddev>0.007</stddev>
      </noise>
    </camera>
    <plugin name="camera_controller" filename="libgazebo_ros_camera.so">
      <alwaysOn>true</alwaysOn>
      <updateRate>0.0</updateRate>
      <cameraName>Kauil/camera1</cameraName>
      <imageTopicName>image_raw</imageTopicName>
      <cameraInfoTopicName>camera_info</cameraInfoTopicName>
      <frameName>camera_link</frameName>
      <hackBaseline>0.07</hackBaseline>
      <distortionK1>0.0</distortionK1>
      <distortionK2>0.0</distortionK2>
      <distortionK3>0.0</distortionK3>
      <distortionT1>0.0</distortionT1>
      <distortionT2>0.0</distortionT2>
    </plugin>
  </sensor>
</gazebo>

</robot>
